<?xml version = "1.0"?>
<robot name = "haptic" xmlns:xacro="http://www.ros.org/wiki/xacro">

  <!-- Used for fixing robot to 'link1' -->
  <link name="world"/>

    <!-- ======================================== Base (Link 5) ============================================== -->
  <link name = "link5">
    <visual>
      <geometry>
        <box size = "0.10 0.50 0.03"/>
      </geometry>
      <material name = "blue"/>
      <origin xyz="-0.25 0 0" rpy="0 0 1.570796326794897" />
    </visual>
    <inertial>
      <mass value="1" />
      <origin xyz="-0.25 0 0" rpy="0 0 1.570796326794897" />
      <inertia ixx="1" ixy="0" ixz="0" iyy="1" iyz="0" izz="1" />
    </inertial>
    <collision>
      <geometry>
        <box size = "0.10 0.50 0.03"/>
      </geometry>
      <material name = "blue"/>
      <origin xyz = "0 0 0"/>
    </collision>
  </link>

  <joint name="base2world" type="fixed">
    <parent link="world"/>
    <child link="link5"/>
  </joint>

  <!-- =============================================== Joint 1 ============================================== -->
  <link name = "revolute1">
    <visual>
      <geometry>
        <cylinder length = "0.1" radius = "0.05"/>
      </geometry>
      <material name = "green"/>
      <origin xyz = "0 0 0.05"/>
    </visual>
    <inertial>
      <mass value="0.15" />
      <origin xyz="0 0 0" rpy="0 0 0" />
      <inertia ixx="0.5" ixy="0" ixz="0" iyy="0.5" iyz="0" izz="0.5" />
    </inertial>
    <collision>
      <geometry>
        <cylinder length = "0.1" radius = "0.05"/>
      </geometry>
      <material name = "green"/>
      <origin xyz = "0 0 0"/>
    </collision>
  </link>

  <joint name = "joint1" type="revolute">
    <parent link = "link5"/>
    <child link = "revolute1"/>
    <origin xyz = "0 0 0" rpy="0 0 0"/>
    <limit effort="1000.0" lower="-1.57" upper="1.57" velocity="0.5"/>
    <axis xyz = "0 0 1"/>
    <dynamics damping="0.2" friction="0.1" />
  </joint>

  <!-- =============================================== Link 1 ============================================== -->
  <link name = "link1">
      <visual>
        <geometry>
          <box size = "0.03 0.1 0.93"/>
        </geometry>
        <material name = "blue"/>
        <origin rpy = "0 1.570796326794897 0" xyz = "0.465 0 0.1"/>
      </visual>
      <inertial>
        <mass value="0.5" />
        <origin xyz="0 0 0" rpy="0 0 0" />
        v<inertia ixx="0.5" ixy="0" ixz="0" iyy="0.5" iyz="0" izz="0.5" />
      </inertial>
      <collision>
        <geometry>
          <box size = "0.1 0.1 0.93"/>
        </geometry>
        <material name = "blue"/>
        <origin rpy = "0 1.571 0" xyz = "0.315 0 -0.25"/>
      </collision>
    </link>

    <joint name = "link12revolute1" type="fixed">
      <parent link = "revolute1"/>
      <child link = "link1"/>
      <origin xyz = "0 0 0"/>
    </joint>

<!-- =============================================== Joint 2 ============================================== -->

  <link name = "revolute2">
    <visual>
      <geometry>
        <cylinder length = "0.1" radius = "0.05"/>
      </geometry>
      <material name = "green"/>
      <origin xyz = "0 0 0"/>
    </visual>
    <inertial>
      <mass value="0.15" />
      <origin xyz="0 0 0" rpy="0 0 0" />
      <inertia ixx="0.5" ixy="0" ixz="0" iyy="0.5" iyz="0" izz="0.5" />
    </inertial>
    <collision>
      <geometry>
        <cylinder length = "0.1" radius = "0.05"/>
      </geometry>
      <material name = "green"/>
      <origin xyz = "0 0 0"/>
    </collision>
  </link>

  <joint name = "joint2" type="revolute">
    <parent link = "link1"/>
    <child link = "revolute2"/>
    <origin xyz = "0.93 0 0.13"/>
    <limit effort="1000.0" lower="-1.57" upper="1.57" velocity="0.5"/>
    <axis xyz = "0 0 1"/>
    <dynamics damping="0.2" friction="0.1" />
  </joint>

<!-- =============================================== Link 2 ============================================== -->
  <!-- link 2 -->
  <link name = "link2">
    <visual>
      <geometry>
        <box size = "0.03 0.1 1.0"/>
      </geometry>
      <material name = "blue"/>
      <origin rpy = "0 1.570796326794897 0" xyz = "0.5 0 0"/>
    </visual>
    <inertial>
      <mass value="0.5" />
      <origin rpy = "0 1.570796326794897 0" xyz = "0.5 0 0"/>
      v<inertia ixx="0.5" ixy="0" ixz="0" iyy="0.5" iyz="0" izz="0.5" />
    </inertial>
    <collision>
      <geometry>
        <box size = "0.03 0.1 0.75"/>
      </geometry>
      <material name = "blue"/>
      <origin rpy = "0 1.570796326794897 0" xyz = "0.5 0 0"/>
    </collision>
  </link>

  <joint name = "link22revolute2" type="fixed">
    <parent link = "revolute2"/>
    <child link = "link2"/>
    <origin xyz = "0 0 0"/>
  </joint>

<!-- =============================================== Joint 3 ============================================== -->
  <link name = "revolute3">
    <visual>
      <geometry>
        <sphere radius="0.025"/>
      </geometry>
      <material name = "orange"/>
      <origin rpy = "0 0 0" xyz = "0 0 0"/>
    </visual>
    <inertial>
      <mass value="0.5" />
      <origin xyz="0 0 0" rpy="0 0 0" />
      v<inertia ixx="0.5" ixy="0" ixz="0" iyy="0.5" iyz="0" izz="0.5" />
    </inertial>
    <collision>
      <geometry>
        <cylinder length = "0.1" radius = "0.05"/>
      </geometry>
      <material name = "orange"/>
      <origin rpy = "0 0 0" xyz = "0 0 0"/>
    </collision>
  </link>

  <joint name = "joint3" type="revolute">
    <parent link = "link2"/>
    <child link = "revolute3"/>
    <origin xyz = "1.0 0 0"/>
    <limit effort="1000.0" lower="-1.57" upper="1.57" velocity="0.5"/>
    <axis xyz = "0 0 1"/>
    <dynamics damping="0.2" friction="0.1" />
  </joint>


<!-- =============================================== Link 3 ============================================== -->

  <link name = "link3">
    <visual>
      <geometry>
        <box size = "0.03 0.1 1.0"/>
      </geometry>
      <material name = "blue"/>
      <origin rpy = "0 1.571 0" xyz = "0.5 0 0"/>
    </visual>
    <inertial>
      <mass value="0.5" />
      <origin rpy = "0 1.571 0" xyz = "0.375 0 0"/>
      v<inertia ixx="0.5" ixy="0" ixz="0" iyy="0.5" iyz="0" izz="0.5" />
    </inertial>
    <collision>
      <geometry>
        <box size = "0.03 0.1 0.63"/>
      </geometry>
      <material name = "blue"/>
      <origin rpy = "0 1.571 0" xyz = "0.375 0 0"/>
    </collision>
  </link>

  <joint name = "link32revolute3" type="fixed">
    <parent link = "revolute3"/>
    <child link = "link3"/>
    <origin xyz = "0 0 0"/>
  </joint>


<!-- =============================================== Joint 5 ============================================== -->

  <link name = "revolute5">
    <visual>
      <geometry>
        <cylinder length = "0.1" radius = "0.05"/>
      </geometry>
      <material name = "green"/>
      <origin xyz = "0 0 0"/>
    </visual>
    <inertial>
      <mass value="0.5" />
      <origin xyz="0 0 0" rpy="0 0 0" />
      <inertia ixx="0.5" ixy="0" ixz="0" iyy="0.5" iyz="0" izz="0.5" />
    </inertial>
    <collision>
      <geometry>
        <cylinder length = "0.1" radius = "0.05"/>
      </geometry>
      <material name = "green"/>
      <origin xyz = "0 0 0.1"/>
    </collision>
  </link>

  <joint name = "joint5" type="revolute">
    <parent link = "link5"/>
    <child link = "revolute5"/>
    <origin xyz = "-0.5 0 0.05" rpy="0 0 0"/>
    <limit effort="1000.0" lower="-1.57" upper="1.57" velocity="0.5"/>
    <axis xyz = "0 0 1"/>
    <dynamics damping="0.2" friction="0.1" />
  </joint>

<!-- =============================================== Link 4 ============================================== -->

  <link name = "link4">
    <visual>
      <geometry>
        <box size = "0.03 0.1 0.93"/>
      </geometry>
      <material name = "blue"/>
      <origin rpy = "0 1.571 0" xyz = "0.465 0.0 0.05"/>
    </visual>
    <inertial>
      <mass value="0.5" />
      <origin xyz="0.315 0 -0.25" rpy="0 0 0" />
      v<inertia ixx="0.5" ixy="0" ixz="0" iyy="0.5" iyz="0" izz="0.5" />
    </inertial>
    <collision>
      <geometry>
        <box size = "0.1 0.1 0.425"/>
      </geometry>
      <material name = "blue"/>
      <origin rpy = "0 1.571 0" xyz = "0.315 0 -0.25"/>
    </collision>
  </link>

  <joint name = "link42revolute5" type="fixed">
    <parent link = "revolute5"/>
    <child link = "link4"/>
    <origin xyz = "0 0 0"/>
  </joint>
     
<!-- =============================================== Joint 4 ============================================== -->

  <link name = "revolute4">
    <visual>
      <geometry>
        <cylinder length = "0.1" radius = "0.05"/>
      </geometry>
      <material name = "green"/>
      <origin rpy = "0 0 0" xyz = "0 0 0"/>
    </visual>
    <inertial>
      <mass value="0.5" />
      <origin xyz="0 0 0" rpy="0 0 0" />
      v<inertia ixx="0.5" ixy="0" ixz="0" iyy="0.5" iyz="0" izz="0.5" />
    </inertial>
    <collision>
      <geometry>
        <cylinder length = "0.1" radius = "0.05"/>
      </geometry>
      <material name = "green"/>
      <origin rpy = "0 0 0" xyz = "0 0 0"/>
    </collision>
  </link>

  <joint name = "joint4" type="revolute">
    <parent link = "link4"/>
    <child link = "revolute4"/>
    <origin xyz = "0.93 0 0.08"/>
    <limit effort="1000.0" lower="-1.57" upper="1.57" velocity="0.5"/>
    <axis xyz = "0 0 1"/>
    <dynamics damping="0.2" friction="0.1" />
  </joint>


  <link name="tool0"/>

  <joint name="tool02revolute1" type="fixed">
      <origin rpy="0 0 0" xyz="0 0 0"/>
      <parent link="revolute1"/>
      <child link="tool0"/>
      <axis xyz="0 0 0"/>
  </joint>

</robot>